Workbook

Sheet 說明
A1: 1019課程版本：各出版商國高中課本目錄統整
A3: 資料範圍
A4: 國中：翰林、康軒、南一，7–9 年級上下冊。國文、英文、數學、自然（生物、理化、地球科學）、社會（歷史、地理、公民）。
A5: 高中：三民、龍騰、南一、全華、泰宇。10 科部定必修與加深加廣選修。
A6: 以 115 學年度現行版本為準；只找到 114 學年度資料時，「學年度」欄會註明。
A8: 資料來源與限制
A9: 蒐集時，出版商官網在作業環境中無法連線（網路政策阻擋），因此本版資料來自網路搜尋，主要是各校公開的課程計畫與教學計畫表，每列都附來源網址。
A10: 只收錄來源中實際看到、且明確標示版本的章節；查不到的冊次保留一列，章節空白（黃底），不做推測。
A11: 學校課程計畫的單元名稱可能經過學校簡化或調整，與課本原文可能有些微差異；以出版商官網或課本為準。
A12: 待辦：開放出版商網域後，到官網逐冊核對，並補上空白冊次；核對過的列，「來源類型」會改為「出版商官網」。
A13: 官網網域：翰林 hle.com.tw、康軒 knsh.com.tw、南一 nani.com.tw、三民 sanmin.com.tw、龍騰 ltedu.com.tw、全華 chwa.com.tw、泰宇 tyedu.com.tw（泰宇待確認）。
A15: 欄位說明
... A19: 目前共 1293 列，其中 988 列有章節內容。

Sheet 國中
A1: 版本 | B1: 學段 | C1: 年級 | D1: 冊次 | E1: 科目 | F1: 章 | G1: 節 | H1: 學年度 | I1: 來源類型 | J1: 來源網址 | K1: 備註
A2: 翰林 | B2: 國中 | C2: 7 | D2: 上 | E2: 國文 | F2: 第一課 夏夜 | H2: 115 | I2: 出版商頁面 | J2: https://sites.google.com/hanlin.com.tw/112chwebppt/1%E4%B8%8A | K2: 來源為翰林官方Google Sites「國文網頁版PPT」課次清單，頁面標示【115上】入口；經搜尋摘要擷取，非直接開啟頁面
A3: 翰林 | B3: 國中 | C3: 7 | D3: 上 | E3: 國文 | F3: 第二課 無心的錯誤 | H3: 115 | I3: 出版商頁面 | J3: https://sites.google.com/hanlin.com.tw/112chwebppt/1%E4%B8%8A | K3: 來源為翰林官方Google Sites「國文網頁版PPT」課次清單，頁面標示【115上】入口；經搜尋摘要擷取，非直接開啟頁面
A4: 翰林 | B4: 國中 | C4: 7 | D4: 上 | E4: 國文 | F4: 第三課 母親的教誨 | H4: 115 | I4: 出版商頁面 | J4: https://sites.google.com/hanlin.com.tw/112chwebppt/1%E4%B8%8A | K4: 來源為翰林官方Google Sites「國文網頁版PPT」課次清單，頁面標示【115上】入口；經搜尋摘要擷取，非直接開啟頁面
A5: 翰林 | B5: 國中 | C5: 7 | D5: 上 | E5: 國文 | F5: 語文常識一 標點符號使用法 | H5: 115 | I5: 出版商頁面 | J5: https://sites.google.com/hanlin.com.tw/112chwebppt/1%E4%B8%8A | K5: 來源為翰林官方Google Sites「國文網頁版PPT」課次清單，頁面標示【115上】入口；經搜尋摘要擷取，非直接開啟頁面
A6: 翰林 | B6: 國中 | C6: 7 | D6: 上 | E6: 國文 | F6: 第四課 論語選 | H6: 115 | I6: 出版商頁面 | J6: https://sites.google.com/hanlin.com.tw/112chwebppt/1%E4%B8%8A | K6: 來源為翰林官方Google Sites「國文網頁版PPT」課次清單，頁面標示【115上】入口；經搜尋摘要擷取，非直接開啟頁面
A7: 翰林 | B7: 國中 | C7: 7 | D7: 上 | E7: 國文 | F7: 第五課 背影 | H7: 115 | I7: 出版商頁面 | J7: https://sites.google.com/hanlin.com.tw/112chwebppt/1%E4%B8%8A | K7: 來源為翰林官方Google Sites「國文網頁版PPT」課次清單，頁面標示【115上】入口；經搜尋摘要擷取，非直接開啟頁面
A8: 翰林 | B8: 國中 | C8: 7 | D8: 上 | E8: 國文 | F8: 第六課 心囚 | H8: 115 | I8: 出版商頁面 | J8: https://sites.google.com/hanlin.com.tw/112chwebppt/1%E4%B8%8A | K8: 來源為翰林官方Google Sites「國文網頁版PPT」課次清單，頁面標示【115上】入口；經搜尋摘要擷取，非直接開啟頁面
A9: 翰林 | B9: 國中 | C9: 7 | D9: 上 | E9: 國文 | F9: 語文常識二 策略運用與資訊檢索 | H9: 115 | I9: 出版商頁面 | J9: https://sites.google.com/hanlin.com.tw/112chwebppt/1%E4%B8%8A | K9: 來源為翰林官方Google Sites「國文網頁版PPT」課次清單，頁面標示【115上】入口；經搜尋摘要擷取，非直接開啟頁面
A10: 翰林 | B10: 國中 | C10: 7 | D10: 上 | E10: 國文 | F10: 第七課 兒時記趣 | H10: 115 | I10: 出版商頁面 | J10: https://sites.google.com/hanlin.com.tw/112chwebppt/1%E4%B8%8A | K10: 來源為翰林官方Google Sites「國文網頁版PPT」課次清單，頁面標示【115上】入口；經搜尋摘要擷取，非直接開啟頁面
A11: 翰林 | B11: 國中 | C11: 7 | D11: 上 | E11: 國文 | F11: 第八課 朋友相交 | H11: 115 | I11: 出版商頁面 | J11: https://sites.google.com/hanlin.com.tw/112chwebppt/1%E4%B8%8A | K11: 來源為翰林官方Google Sites「國文網頁版PPT」課次清單，頁面標示【115上】入口；經搜尋摘要擷取，非直接開啟頁面
A12: 翰林 | B12: 國中 | C12: 7 | D12: 上 | E12: 國文 | F12: 第九課 音樂家與職籃巨星 | H12: 115 | I12: 出版商頁面 | J12: https://sites.google.com/hanlin.com.tw/112chwebppt/1%E4%B8%8A | K12: 來源為翰林官方Google Sites「國文網頁版PPT」課次清單，頁面標示【115上】入口；經搜尋摘要擷取，非直接開啟頁面
A13: 翰林 | B13: 國中 | C13: 7 | D13: 上 | E13: 國文 | F13: 第十課 玫瑰淚 | H13: 115 | I13: 出版商頁面 | J13: https://sites.google.com/hanlin.com.tw/112chwebppt/1%E4%B8%8A | K13: 來源為翰林官方Google Sites「國文網頁版PPT」課次清單，頁面標示【115上】入口；經搜尋摘要擷取，非直接開啟頁面；翰林114學年度「數位互動資源平台」將L10列為〈藍色串珠項鍊〉，與此處不同
... A115: 翰林 | B115: 國中 | C115: 9 | D115: 下 | E115: 英文 | F115: Unit 4 Let’s Vote | H115: 115 | I115: 出版商官網 | J115: https://dl.hle.com.tw/1151/國中/01課程計畫/115翰林課程計畫_英語教學進度總表.zip | K115: 來源為翰林官網行動大師「115課程計畫-教學進度總表」壓縮檔內《115三下英語(二次段考)課程總表.doc》;Review單元及延伸活動未列入,節未列;主題:台灣的公民參與
A116: 翰林 | B116: 國中 | C116: 7 | D116: 上 | E116: 數學 | F116: 第1章 數與數線 | G116: 1-1 正數與負數；1-2 正負數的加減；1-3 正負數的乘除；1-4 指數記法與科學記號 | H116: 115 | I116: 出版商官網 | J116: https://dl.hle.com.tw/1151/國中/01課程計畫/115翰林課程計畫_數學教學進度總表.zip | K116: 來源為翰林官網行動大師「115課程計畫-教學進度總表」壓縮檔內《115一上數學(三次段考)課程總表.doc》;節名取自進度表;進度表僅列「節」編號,未含實驗等細項
A117: 翰林 | B117: 國中 | C117: 7 | D117: 上 | E117: 數學 | F117: 第2章 標準分解式與分數運算 | G117: 2-1 質因數分解；2-2 最大公因數與最小公倍數；2-3 分數的四則運算；2-4 指數律 | H117: 115 | I117: 出版商官網 | J117: https://dl.hle.com.tw/1151/國中/01課程計畫/115翰林課程計畫_數學教學進度總表.zip | K117: 來源為翰林官網行動大師「115課程計畫-教學進度總表」壓縮檔內《115一上數學(三次段考)課程總表.doc》;節名取自進度表;進度表僅列「節」編號,未含實驗等細項
A118: 翰林 | B118: 國中 | C118: 7 | D118: 上 | E118: 數學 | F118: 第3章 一元一次方程式 | G118: 3-1 式子的運算；3-2 解一元一次方程式；3-3 應用問題 | H118: 115 | I118: 出版商官網 | J118: https://dl.hle.com.tw/1151/國中/01課程計畫/115翰林課程計畫_數學教學進度總表.zip | K118: 來源為翰林官網行動大師「115課程計畫-教學進度總表」壓縮檔內《115一上數學(三次段考)課程總表.doc》;節名取自進度表;進度表僅列「節」編號,未含實驗等細項
A119: 翰林 | B119: 國中 | C119: 7 | D119: 下 | E119: 數學 | F119: 第1章 二元一次聯立方程式 | G119: 1-1 二元一次方程式；1-2 解二元一次聯立方程式；1-3 應用問題 | H119: 115 | I119: 出版商官網 | J119: https://dl.hle.com.tw/1151/國中/01課程計畫/115翰林課程計畫_數學教學進度總表.zip | K119: 來源為翰林官網行動大師「115課程計畫-教學進度總表」壓縮檔內《115一下數學(三次段考)課程總表.doc》;節名取自進度表;進度表僅列「節」編號,未含實驗等細項
A120: 翰林 | B120: 國中 | C120: 7 | D120: 下 | E120: 數學 | F120: 第2章 直角坐標與二元一次方程式的圖形 | G120: 2-1 直角坐標平面；2-2 二元一次方程式的圖形 | H120: 115 | I120: 出版商官網 | J120: https://dl.hle.com.tw/1151/國中/01課程計畫/115翰林課程計畫_數學教學進度總表.zip | K120: 來源為翰林官網行動大師「115課程計畫-教學進度總表」壓縮檔內《115一下數學(三次段考)課程總表.doc》;節名取自進度表;進度表僅列「節」編號,未含實驗等細項
A121: 翰林 | B121: 國中 | C121: 7 | D121: 下 | E121: 數學 | F121: 第3章 比例 | G121: 3-1 比例式；3-2 正比與反比 | H121: 115 | I121: 出版商官網 | J121: https://dl.hle.com.tw/1151/國中/01課程計畫/115翰林課程計畫_數學教學進度總表.zip | K121: 來源為翰林官網行動大師「115課程計畫-教學進度總表」壓縮檔內《115一下數學(三次段考)課程總表.doc》;節名取自進度表;進度表僅列「節」編號,未含實驗等細項
A122: 翰林 | B122: 國中 | C122: 7 | D122: 下 | E122: 數學 | F122: 第4章 一元一次不等式 | G122: 4-1 一元一次不等式的解及圖示；4-2 解一元一次不等式及其應用 | H122: 115 | I122: 出版商官網 | J122: https://dl.hle.com.tw/1151/國中/01課程計畫/115翰林課程計畫_數學教學進度總表.zip | K122: 來源為翰林官網行動大師「115課程計畫-教學進度總表」壓縮檔內《115一下數學(三次段考)課程總表.doc》;節名取自進度表;進度表僅列「節」編號,未含實驗等細項
A123: 翰林 | B123: 國中 | C123: 7 | D123: 下 | E123: 數學 | F123: 第5章 統計圖表與統計數據 | H123: 115 | I123: 出版商官網 | J123: https://dl.hle.com.tw/1151/國中/01課程計畫/115翰林課程計畫_數學教學進度總表.zip | K123: 來源為翰林官網行動大師「115課程計畫-教學進度總表」壓縮檔內《115一下數學(三次段考)課程總表.doc》;節名取自進度表;進度表僅列「節」編號,未含實驗等細項
A124: 翰林 | B124: 國中 | C124: 7 | D124: 下 | E124: 數學 | F124: 第6章 線對稱與三視圖 | H124: 115 | I124: 出版商官網 | J124: https://dl.hle.com.tw/1151/國中/01課程計畫/115翰林課程計畫_數學教學進度總表.zip | K124: 來源為翰林官網行動大師「115課程計畫-教學進度總表」壓縮檔內《115一下數學(三次段考)課程總表.doc》;節名取自進度表;進度表僅列「節」編號,未含實驗等細項
A125: 翰林 | B125: 國中 | C125: 8 | D125: 上 | E125: 數學 | F125: 第1章 乘法公式與多項式 | G125: 1-1 乘法公式；1-2 多項式的加減；1-3 多項式的乘除 | H125: 115 | I125: 出版商官網 | J125: https://dl.hle.com.tw/1151/國中/01課程計畫/115翰林課程計畫_數學教學進度總表.zip | K125: 來源為翰林官網行動大師「115課程計畫-教學進度總表」壓縮檔內《115二上數學(三次段考)課程總表.doc》;節名取自進度表;進度表僅列「節」編號,未含實驗等細項
A126: 翰林 | B126: 國中 | C126: 8 | D126: 上 | E126: 數學 | F126: 第2章 二次方根與畢氏定理 | G126: 2-1 二次方根的意義；2-2 根式的運算；2-3 畢氏定理 | H126: 115 | I126: 出版商官網 | J126: https://dl.hle.com.tw/1151/國中/01課程計畫/115翰林課程計畫_數學教學進度總表.zip | K126: 來源為翰林官網行動大師「115課程計畫-教學進度總表」壓縮檔內《115二上數學(三次段考)課程總表.doc》;節名取自進度表;進度表僅列「節」編號,未含實驗等細項
A127: 翰林 | B127: 國中 | C127: 8 | D127: 上 | E127: 數學 | F127: 第3章 因式分解 | G127: 3-1 提公因式與乘法公式作因式分解；3-2 利用十字交乘法因式分解 | H127: 115 | I127: 出版商官網 | J127: https://dl.hle.com.tw/1151/國中/01課程計畫/115翰林課程計畫_數學教學進度總表.zip | K127: 來源為翰林官網行動大師「115課程計畫-教學進度總表」壓縮檔內《115二上數學(三次段考)課程總表.doc》;節名取自進度表;進度表僅列「節」編號,未含實驗等細項
A128: 翰林 | B128: 國中 | C128: 8 | D128: 上 | E128: 數學 | F128: 第4章 一元二次方程式 | G128: 4-1 因式分解法解一元二次方程式；4-2 配方法與公式解；4-3 應用問題 | H128: 115 | I128: 出版商官網 | J128: https://dl.hle.com.tw/1151/國中/01課程計畫/115翰林課程計畫_數學教學進度總表.zip | K128: 來源為翰林官網行動大師「115課程計畫-教學進度總表」壓縮檔內《115二上數學(三次段考)課程總表.doc》;節名取自進度表;進度表僅列「節」編號,未含實驗等細項
A129: 翰林 | B129: 國中 | C129: 8 | D129: 上 | E129: 數學 | F129: 第5章 統計資料處理 | H129: 115 | I129: 出版商官網 | J129: https://dl.hle.com.tw/1151/國中/01課程計畫/115翰林課程計畫_數學教學進度總表.zip | K129: 來源為翰林官網行動大師「115課程計畫-教學進度總表」壓縮檔內《115二上數學(三次段考)課程總表.doc》;節名取自進度表;進度表僅列「節」編號,未含實驗等細項
A130: 翰林 | B130: 國中 | C130: 8 | D130: 下 | E130: 數學 | F130: 第1章 數列與級數 | G130: 1-1 認識數列與等差數列；1-2 等差級數；1-3 等比數列 | H130: 115 | I130: 出版商官網 | J130: https://dl.hle.com.tw/1151/國中/01課程計畫/115翰林課程計畫_數學教學進度總表.zip | K130: 來源為翰林官網行動大師「115課程計畫-教學進度總表」壓縮檔內《115二下數學(三次段考)課程總表.doc》;節名取自進度表;進度表僅列「節」編號,未含實驗等細項
A131: 翰林 | B131: 國中 | C131: 8 | D131: 下 | E131: 數學 | F131: 第2章 線型函數與其圖形 | H131: 115 | I131: 出版商官網 | J131: https://dl.hle.com.tw/1151/國中/01課程計畫/115翰林課程計畫_數學教學進度總表.zip | K131: 來源為翰林官網行動大師「115課程計畫-教學進度總表」壓縮檔內《115二下數學(三次段考)課程總表.doc》;節名取自進度表;進度表僅列「節」編號,未含實驗等細項
A132: 翰林 | B132: 國中 | C132: 8 | D132: 下 | E132: 數學 | F132: 第3章 三角形的基本性質 | G132: 3-1 內角與外角；3-2 基本的尺規作圖；3-3 三角形的全等性質；3-4 中垂線與角平分線性質；3-5 三角形的邊角關係 | H132: 115 | I132: 出版商官網 | J132: https://dl.hle.com.tw/1151/國中/01課程計畫/115翰林課程計畫_數學教學進度總表.zip | K132: 來源為翰林官網行動大師「115課程計畫-教學進度總表」壓縮檔內《115二下數學(三次段考)課程總表.doc》;節名取自進度表;進度表僅列「節」編號,未含實驗等細項
A133: 翰林 | B133: 國中 | C133: 8 | D133: 下 | E133: 數學 | F133: 第4章 平行與四邊形 | G133: 4-1 平行線與截角性質；4-2 平行四邊形；4-3 特殊四邊形 | H133: 115 | I133: 出版商官網 | J133: https://dl.hle.com.tw/1151/國中/01課程計畫/115翰林課程計畫_數學教學進度總表.zip | K133: 來源為翰林官網行動大師「115課程計畫-教學進度總表」壓縮檔內《115二下數學(三次段考)課程總表.doc》;節名取自進度表;進度表僅列「節」編號,未含實驗等細項
A134: 翰林 | B134: 國中 | C134: 9 | D134: 上 | E134: 數學 | F134: 第1章 相似形與三角比 | G134: 1-1 連比；1-2 比例線段；1-3 相似多邊形；1-4 相似三角形的應用與三角比 | H134: 115 | I134: 出版商官網 | J134: https://dl.hle.com.tw/1151/國中/01課程計畫/115翰林課程計畫_數學教學進度總表.zip | K134: 來源為翰林官網行動大師「115課程計畫-教學進度總表」壓縮檔內《115三上數學(三次段考)課程總表.doc》;節名取自進度表;進度表僅列「節」編號,未含實驗等細項
A135: 翰林 | B135: 國中 | C135: 9 | D135: 上 | E135: 數學 | F135: 第2章 圓形 | G135: 2-1 點、線、圓；2-2 圓心角與圓周角 | H135: 115 | I135: 出版商官網 | J135: https://dl.hle.com.tw/1151/國中/01課程計畫/115翰林課程計畫_數學教學進度總表.zip | K135: 來源為翰林官網行動大師「115課程計畫-教學進度總表」壓縮檔內《115三上數學(三次段考)課程總表.doc》;節名取自進度表;進度表僅列「節」編號,未含實驗等細項
A136: 翰林 | B136: 國中 | C136: 9 | D136: 上 | E136: 數學 | F136: 第3章 推理證明與三角形的心 | G136: 3-1 推理證明；3-2 三角形的外心、內心與重心 | H136: 115 | I136: 出版商官網 | J136: https://dl.hle.com.tw/1151/國中/01課程計畫/115翰林課程計畫_數學教學進度總表.zip | K136: 來源為翰林官網行動大師「115課程計畫-教學進度總表」壓縮檔內《115三上數學(三次段考)課程總表.doc》;節名取自進度表;進度表僅列「節」編號,未含實驗等細項
A137: 翰林 | B137: 國中 | C137: 9 | D137: 下 | E137: 數學 | F137: 第1章 二次函數 | G137: 1-1 基本二次函數的圖形；1-2 二次函數圖形與最大值、最小值 | H137: 115 | I137: 出版商官網 | J137: https://dl.hle.com.tw/1151/國中/01課程計畫/115翰林課程計畫_數學教學進度總表.zip | K137: 來源為翰林官網行動大師「115課程計畫-教學進度總表」壓縮檔內《115三下數學(二次段考)課程總表.doc》;節名取自進度表;進度表僅列「節」編號,未含實驗等細項
A138: 翰林 | B138: 國中 | C138: 9 | D138: 下 | E138: 數學 | F138: 第2章 統計與機率 | G138: 2-1 四分位數與盒狀圖；2-2 機率 | H138: 115 | I138: 出版商官網 | J138: https://dl.hle.com.tw/1151/國中/01課程計畫/115翰林課程計畫_數學教學進度總表.zip | K138: 來源為翰林官網行動大師「115課程計畫-教學進度總表」壓縮檔內《115三下數學(二次段考)課程總表.doc》;節名取自進度表;進度表僅列「節」編號,未含實驗等細項
A139: 翰林 | B139: 國中 | C139: 9 | D139: 下 | E139: 數學 | F139: 第3章 立體圖形 | H139: 115 | I139: 出版商官網 | J139: https://dl.hle.com.tw/1151/國中/01課程計畫/115翰林課程計畫_數學教學進度總表.zip | K139: 來源為翰林官網行動大師「115課程計畫-教學進度總表」壓縮檔內《115三下數學(二次段考)課程總表.doc》;節名取自進度表;進度表僅列「節」編號,未含實驗等細項
A140: 翰林 | B140: 國中 | C140: 7 | D140: 上 | E140: 生物 | F140: 第1章 生命世界與科學方法 | G140: 1-1 多采多姿的生命世界；1-2 探究自然的科學方法；1-3 進入實驗室 | H140: 115 | I140: 出版商官網 | J140: https://dl.hle.com.tw/1151/國中/01課程計畫/115翰林課程計畫_自然教學進度總表.zip | K140: 來源為翰林官網行動大師「115課程計畫-教學進度總表」壓縮檔內《115一上自然(三次段考)課程總表.doc》;節名取自進度表,實驗/探討活動未列入
A141: 翰林 | B141: 國中 | C141: 7 | D141: 上 | E141: 生物 | F141: 第2章 生物體的組成 | G141: 2-1 生物的基本單位；2-2 細胞的構造；2-3 物質進出細胞的方式；2-4 生物體的組成層次 | H141: 115 | I141: 出版商官網 | J141: https://dl.hle.com.tw/1151/國中/01課程計畫/115翰林課程計畫_自然教學進度總表.zip | K141: 來源為翰林官網行動大師「115課程計畫-教學進度總表」壓縮檔內《115一上自然(三次段考)課程總表.doc》;節名取自進度表,實驗/探討活動未列入
...

Sheet 高中
A1: 版本 | B1: 學段 | C1: 年級 | D1: 冊次 | E1: 科目 | F1: 章 | G1: 節 | H1: 學年度 | I1: 來源類型 | J1: 來源網址 | K1: 備註
A2: 南一 | B2: 高中 | C2: 10 | D2: 第一冊 | E2: 國文 | K2: 未查到
A3: 南一 | B3: 高中 | C3: 10 | D3: 第二冊 | E3: 國文 | K3: 未查到
A4: 南一 | B4: 高中 | C4: 11 | D4: 第三冊 | E4: 國文 | K4: 未查到
A5: 南一 | B5: 高中 | C5: 11 | D5: 第四冊 | E5: 國文 | K5: 未查到
A6: 南一 | B6: 高中 | C6: 12 | D6: 第五冊 | E6: 國文 | K6: 未查到
A7: 南一 | B7: 高中 | C7: 12 | D7: 第六冊 | E7: 國文 | K7: 未查到
A8: 南一 | B8: 高中 | D8: 加深加廣選修：各類文學選讀 | E8: 國文 | K8: 未查到
A9: 南一 | B9: 高中 | D9: 加深加廣選修：國學常識 | E9: 國文 | K9: 未查到
A10: 南一 | B10: 高中 | D10: 加深加廣選修：專題閱讀與研究 | E10: 國文 | K10: 未查到
A11: 南一 | B11: 高中 | D11: 加深加廣選修：語文表達及傳播應用 | E11: 國文 | K11: 未查到
A12: 南一 | B12: 高中 | C12: 10 | D12: 第一冊 | E12: 英文 | K12: 未查到
A13: 南一 | B13: 高中 | C13: 10 | D13: 第二冊 | E13: 英文 | K13: 未查到
A14: 南一 | B14: 高中 | C14: 11 | D14: 第三冊 | E14: 英文 | K14: 未查到
A15: 南一 | B15: 高中 | C15: 11 | D15: 第四冊 | E15: 英文 | K15: 未查到
A16: 南一 | B16: 高中 | C16: 12 | D16: 第五冊 | E16: 英文 | K16: 未查到
A17: 南一 | B17: 高中 | C17: 12 | D17: 第六冊 | E17: 英文 | K17: 未查到
A18: 南一 | B18: 高中 | D18: 加深加廣選修：英文閱讀與寫作 | E18: 英文 | K18: 未查到
A19: 南一 | B19: 高中 | D19: 加深加廣選修：英語聽講 | E19: 英文 | K19: 未查到
A20: 南一 | B20: 高中 | C20: 10 | D20: 第一冊 | E20: 數學 | K20: 未查到（南一官方商城有「高中數學(一)課本【114上適用】」商品頁 https://shop.nani1953.com.tw/products/%E9%AB%98%E4%B8%AD%E6%95%B8%E5%AD%B8%E4%B8%80%E8%AA%B2%E6%9C%AC ，但未見目錄）
A21: 南一 | B21: 高中 | C21: 10 | D21: 第二冊 | E21: 數學 | K21: 未查到（南一商城有「高中數學(二)課本【113下適用】」商品頁，未見目錄）
A22: 南一 | B22: 高中 | C22: 11 | D22: 第三冊A | E22: 數學 | K22: 未查到
A23: 南一 | B23: 高中 | C23: 11 | D23: 第三冊B | E23: 數學 | K23: 未查到
A24: 南一 | B24: 高中 | C24: 11 | D24: 第四冊A | E24: 數學 | K24: 未查到
A25: 南一 | B25: 高中 | C25: 11 | D25: 第四冊B | E25: 數學 | K25: 未查到
A26: 南一 | B26: 高中 | C26: 12 | D26: 數學乙上 | E26: 數學 | K26: 未查到
A27: 南一 | B27: 高中 | C27: 12 | D27: 數學乙下 | E27: 數學 | K27: 未查到
A28: 南一 | B28: 高中 | C28: 12 | D28: 數學甲上 | E28: 數學 | K28: 未查到
A29: 南一 | B29: 高中 | C29: 12 | D29: 數學甲下 | E29: 數學 | K29: 未查到（南一商城有「高中選修數學甲下(乙版)課本【114下適用】」商品頁，未見目錄）
A30: 南一 | B30: 高中 | D30: 基礎生物（一） | E30: 生物 | I30: 其他 | K30: 未查到章節；師大附中111學年度資料顯示曾用南一版生物(全)，但沒有單元名稱
A31: 南一 | B31: 高中 | D31: 基礎生物（二） | E31: 生物 | I31: 其他 | K31: 未查到
A32: 南一 | B32: 高中 | D32: 選修生物I | E32: 生物 | I32: 其他 | K32: 未查到章節；師大附中112-2資料顯示曾用南一版選修生物，但沒有單元名稱與冊次
A33: 南一 | B33: 高中 | D33: 選修生物II | E33: 生物 | I33: 其他 | K33: 未查到
A34: 南一 | B34: 高中 | D34: 選修生物III | E34: 生物 | I34: 其他 | K34: 未查到
A35: 南一 | B35: 高中 | D35: 選修生物IV | E35: 生物 | I35: 其他 | K35: 未查到
A36: 南一 | B36: 高中 | D36: 基礎物理（一） | E36: 物理 | I36: 其他 | K36: 未查到
A37: 南一 | B37: 高中 | D37: 選修物理I | E37: 物理 | I37: 其他 | K37: 未查到
A38: 南一 | B38: 高中 | D38: 選修物理II | E38: 物理 | I38: 其他 | K38: 未查到
A39: 南一 | B39: 高中 | D39: 選修物理III | E39: 物理 | I39: 其他 | K39: 未查到
A40: 南一 | B40: 高中 | D40: 選修物理IV | E40: 物理 | I40: 其他 | K40: 未查到
...

Sheet 涵蓋總覽
A1: 學段 | B1: 版本 | C1: 科目 | D1: 年級 | E1: 冊次 | F1: 已查到章（課）數 | G1: 狀態
A2: 國中 | B2: 翰林 | C2: 國文 | D2: 7 | E2: 上 | F2: =COUNTIFS(國中!$A:$A,$B2,國中!$E:$E,$C2,國中!$F:$F,"<>",國中!$C:$C,$D2,國中!$D:$D,$E2) | G2: =IF(F2>0,"已查到","未查到")
A3: 國中 | B3: 翰林 | C3: 國文 | D3: 7 | E3: 下 | F3: =COUNTIFS(國中!$A:$A,$B3,國中!$E:$E,$C3,國中!$F:$F,"<>",國中!$C:$C,$D3,國中!$D:$D,$E3) | G3: =IF(F3>0,"已查到","未查到")
A4: 國中 | B4: 翰林 | C4: 國文 | D4: 8 | E4: 上 | F4: =COUNTIFS(國中!$A:$A,$B4,國中!$E:$E,$C4,國中!$F:$F,"<>",國中!$C:$C,$D4,國中!$D:$D,$E4) | G4: =IF(F4>0,"已查到","未查到")
A5: 國中 | B5: 翰林 | C5: 國文 | D5: 8 | E5: 下 | F5: =COUNTIFS(國中!$A:$A,$B5,國中!$E:$E,$C5,國中!$F:$F,"<>",國中!$C:$C,$D5,國中!$D:$D,$E5) | G5: =IF(F5>0,"已查到","未查到")
A6: 國中 | B6: 翰林 | C6: 國文 | D6: 9 | E6: 上 | F6: =COUNTIFS(國中!$A:$A,$B6,國中!$E:$E,$C6,國中!$F:$F,"<>",國中!$C:$C,$D6,國中!$D:$D,$E6) | G6: =IF(F6>0,"已查到","未查到")
A7: 國中 | B7: 翰林 | C7: 國文 | D7: 9 | E7: 下 | F7: =COUNTIFS(國中!$A:$A,$B7,國中!$E:$E,$C7,國中!$F:$F,"<>",國中!$C:$C,$D7,國中!$D:$D,$E7) | G7: =IF(F7>0,"已查到","未查到")
A8: 國中 | B8: 翰林 | C8: 英文 | D8: 7 | E8: 上 | F8: =COUNTIFS(國中!$A:$A,$B8,國中!$E:$E,$C8,國中!$F:$F,"<>",國中!$C:$C,$D8,國中!$D:$D,$E8) | G8: =IF(F8>0,"已查到","未查到")
A9: 國中 | B9: 翰林 | C9: 英文 | D9: 7 | E9: 下 | F9: =COUNTIFS(國中!$A:$A,$B9,國中!$E:$E,$C9,國中!$F:$F,"<>",國中!$C:$C,$D9,國中!$D:$D,$E9) | G9: =IF(F9>0,"已查到","未查到")
A10: 國中 | B10: 翰林 | C10: 英文 | D10: 8 | E10: 上 | F10: =COUNTIFS(國中!$A:$A,$B10,國中!$E:$E,$C10,國中!$F:$F,"<>",國中!$C:$C,$D10,國中!$D:$D,$E10) | G10: =IF(F10>0,"已查到","未查到")
A11: 國中 | B11: 翰林 | C11: 英文 | D11: 8 | E11: 下 | F11: =COUNTIFS(國中!$A:$A,$B11,國中!$E:$E,$C11,國中!$F:$F,"<>",國中!$C:$C,$D11,國中!$D:$D,$E11) | G11: =IF(F11>0,"已查到","未查到")
A12: 國中 | B12: 翰林 | C12: 英文 | D12: 9 | E12: 上 | F12: =COUNTIFS(國中!$A:$A,$B12,國中!$E:$E,$C12,國中!$F:$F,"<>",國中!$C:$C,$D12,國中!$D:$D,$E12) | G12: =IF(F12>0,"已查到","未查到")
A13: 國中 | B13: 翰林 | C13: 英文 | D13: 9 | E13: 下 | F13: =COUNTIFS(國中!$A:$A,$B13,國中!$E:$E,$C13,國中!$F:$F,"<>",國中!$C:$C,$D13,國中!$D:$D,$E13) | G13: =IF(F13>0,"已查到","未查到")
... A95: 國中 | B95: 南一 | C95: 國文 | D95: 9 | E95: 下 | F95: =COUNTIFS(國中!$A:$A,$B95,國中!$E:$E,$C95,國中!$F:$F,"<>",國中!$C:$C,$D95,國中!$D:$D,$E95) | G95: =IF(F95>0,"已查到","未查到")
A96: 高中 | B96: 南一 | C96: 國文 | D96: 10 | E96: 第一冊 | F96: =COUNTIFS(高中!$A:$A,$B96,高中!$E:$E,$C96,高中!$F:$F,"<>",高中!$C:$C,$D96,高中!$D:$D,$E96) | G96: =IF(F96>0,"已查到","未查到")
A97: 高中 | B97: 南一 | C97: 國文 | D97: 10 | E97: 第二冊 | F97: =COUNTIFS(高中!$A:$A,$B97,高中!$E:$E,$C97,高中!$F:$F,"<>",高中!$C:$C,$D97,高中!$D:$D,$E97) | G97: =IF(F97>0,"已查到","未查到")
A98: 高中 | B98: 南一 | C98: 國文 | D98: 11 | E98: 第三冊 | F98: =COUNTIFS(高中!$A:$A,$B98,高中!$E:$E,$C98,高中!$F:$F,"<>",高中!$C:$C,$D98,高中!$D:$D,$E98) | G98: =IF(F98>0,"已查到","未查到")
A99: 高中 | B99: 南一 | C99: 國文 | D99: 11 | E99: 第四冊 | F99: =COUNTIFS(高中!$A:$A,$B99,高中!$E:$E,$C99,高中!$F:$F,"<>",高中!$C:$C,$D99,高中!$D:$D,$E99) | G99: =IF(F99>0,"已查到","未查到")
A100: 高中 | B100: 南一 | C100: 國文 | D100: 12 | E100: 第五冊 | F100: =COUNTIFS(高中!$A:$A,$B100,高中!$E:$E,$C100,高中!$F:$F,"<>",高中!$C:$C,$D100,高中!$D:$D,$E100) | G100: =IF(F100>0,"已查到","未查到")
A101: 高中 | B101: 南一 | C101: 國文 | D101: 12 | E101: 第六冊 | F101: =COUNTIFS(高中!$A:$A,$B101,高中!$E:$E,$C101,高中!$F:$F,"<>",高中!$C:$C,$D101,高中!$D:$D,$E101) | G101: =IF(F101>0,"已查到","未查到")
A102: 高中 | B102: 南一 | C102: 國文 | E102: 加深加廣選修：各類文學選讀 | F102: =COUNTIFS(高中!$A:$A,$B102,高中!$E:$E,$C102,高中!$F:$F,"<>",高中!$C:$C,"",高中!$D:$D,$E102) | G102: =IF(F102>0,"已查到","未查到")
A103: 高中 | B103: 南一 | C103: 國文 | E103: 加深加廣選修：國學常識 | F103: =COUNTIFS(高中!$A:$A,$B103,高中!$E:$E,$C103,高中!$F:$F,"<>",高中!$C:$C,"",高中!$D:$D,$E103) | G103: =IF(F103>0,"已查到","未查到")
A104: 高中 | B104: 南一 | C104: 國文 | E104: 加深加廣選修：專題閱讀與研究 | F104: =COUNTIFS(高中!$A:$A,$B104,高中!$E:$E,$C104,高中!$F:$F,"<>",高中!$C:$C,"",高中!$D:$D,$E104) | G104: =IF(F104>0,"已查到","未查到")
A105: 高中 | B105: 南一 | C105: 國文 | E105: 加深加廣選修：語文表達及傳播應用 | F105: =COUNTIFS(高中!$A:$A,$B105,高中!$E:$E,$C105,高中!$F:$F,"<>",高中!$C:$C,"",高中!$D:$D,$E105) | G105: =IF(F105>0,"已查到","未查到")
A106: 國中 | B106: 南一 | C106: 英文 | D106: 7 | E106: 上 | F106: =COUNTIFS(國中!$A:$A,$B106,國中!$E:$E,$C106,國中!$F:$F,"<>",國中!$C:$C,$D106,國中!$D:$D,$E106) | G106: =IF(F106>0,"已查到","未查到")
A107: 國中 | B107: 南一 | C107: 英文 | D107: 7 | E107: 下 | F107: =COUNTIFS(國中!$A:$A,$B107,國中!$E:$E,$C107,國中!$F:$F,"<>",國中!$C:$C,$D107,國中!$D:$D,$E107) | G107: =IF(F107>0,"已查到","未查到")
A108: 國中 | B108: 南一 | C108: 英文 | D108: 8 | E108: 上 | F108: =COUNTIFS(國中!$A:$A,$B108,國中!$E:$E,$C108,國中!$F:$F,"<>",國中!$C:$C,$D108,國中!$D:$D,$E108) | G108: =IF(F108>0,"已查到","未查到")
A109: 國中 | B109: 南一 | C109: 英文 | D109: 8 | E109: 下 | F109: =COUNTIFS(國中!$A:$A,$B109,國中!$E:$E,$C109,國中!$F:$F,"<>",國中!$C:$C,$D109,國中!$D:$D,$E109) | G109: =IF(F109>0,"已查到","未查到")
A110: 國中 | B110: 南一 | C110: 英文 | D110: 9 | E110: 上 | F110: =COUNTIFS(國中!$A:$A,$B110,國中!$E:$E,$C110,國中!$F:$F,"<>",國中!$C:$C,$D110,國中!$D:$D,$E110) | G110: =IF(F110>0,"已查到","未查到")
A111: 國中 | B111: 南一 | C111: 英文 | D111: 9 | E111: 下 | F111: =COUNTIFS(國中!$A:$A,$B111,國中!$E:$E,$C111,國中!$F:$F,"<>",國中!$C:$C,$D111,國中!$D:$D,$E111) | G111: =IF(F111>0,"已查到","未查到")
A112: 高中 | B112: 南一 | C112: 英文 | D112: 10 | E112: 第一冊 | F112: =COUNTIFS(高中!$A:$A,$B112,高中!$E:$E,$C112,高中!$F:$F,"<>",高中!$C:$C,$D112,高中!$D:$D,$E112) | G112: =IF(F112>0,"已查到","未查到")
A113: 高中 | B113: 南一 | C113: 英文 | D113: 10 | E113: 第二冊 | F113: =COUNTIFS(高中!$A:$A,$B113,高中!$E:$E,$C113,高中!$F:$F,"<>",高中!$C:$C,$D113,高中!$D:$D,$E113) | G113: =IF(F113>0,"已查到","未查到")
A114: 高中 | B114: 南一 | C114: 英文 | D114: 11 | E114: 第三冊 | F114: =COUNTIFS(高中!$A:$A,$B114,高中!$E:$E,$C114,高中!$F:$F,"<>",高中!$C:$C,$D114,高中!$D:$D,$E114) | G114: =IF(F114>0,"已查到","未查到")
A115: 高中 | B115: 南一 | C115: 英文 | D115: 11 | E115: 第四冊 | F115: =COUNTIFS(高中!$A:$A,$B115,高中!$E:$E,$C115,高中!$F:$F,"<>",高中!$C:$C,$D115,高中!$D:$D,$E115) | G115: =IF(F115>0,"已查到","未查到")
A116: 高中 | B116: 南一 | C116: 英文 | D116: 12 | E116: 第五冊 | F116: =COUNTIFS(高中!$A:$A,$B116,高中!$E:$E,$C116,高中!$F:$F,"<>",高中!$C:$C,$D116,高中!$D:$D,$E116) | G116: =IF(F116>0,"已查到","未查到")
A117: 高中 | B117: 南一 | C117: 英文 | D117: 12 | E117: 第六冊 | F117: =COUNTIFS(高中!$A:$A,$B117,高中!$E:$E,$C117,高中!$F:$F,"<>",高中!$C:$C,$D117,高中!$D:$D,$E117) | G117: =IF(F117>0,"已查到","未查到")
A118: 高中 | B118: 南一 | C118: 英文 | E118: 加深加廣選修：英文閱讀與寫作 | F118: =COUNTIFS(高中!$A:$A,$B118,高中!$E:$E,$C118,高中!$F:$F,"<>",高中!$C:$C,"",高中!$D:$D,$E118) | G118: =IF(F118>0,"已查到","未查到")
A119: 高中 | B119: 南一 | C119: 英文 | E119: 加深加廣選修：英語聽講 | F119: =COUNTIFS(高中!$A:$A,$B119,高中!$E:$E,$C119,高中!$F:$F,"<>",高中!$C:$C,"",高中!$D:$D,$E119) | G119: =IF(F119>0,"已查到","未查到")
A120: 國中 | B120: 南一 | C120: 數學 | D120: 7 | E120: 上 | F120: =COUNTIFS(國中!$A:$A,$B120,國中!$E:$E,$C120,國中!$F:$F,"<>",國中!$C:$C,$D120,國中!$D:$D,$E120) | G120: =IF(F120>0,"已查到","未查到")
A121: 國中 | B121: 南一 | C121: 數學 | D121: 7 | E121: 下 | F121: =COUNTIFS(國中!$A:$A,$B121,國中!$E:$E,$C121,國中!$F:$F,"<>",國中!$C:$C,$D121,國中!$D:$D,$E121) | G121: =IF(F121>0,"已查到","未查到")
...
